Failure # 1 (occurred at 2022-03-27_10-59-05)
Traceback (most recent call last):
  File "/usr/local/anaconda3/envs/edge-cloud-resource-allocation/lib/python3.6/site-packages/ray/tune/trial_runner.py", line 897, in _process_trial
    results = self.trial_executor.fetch_result(trial)
  File "/usr/local/anaconda3/envs/edge-cloud-resource-allocation/lib/python3.6/site-packages/ray/tune/ray_trial_executor.py", line 707, in fetch_result
    result = ray.get(trial_future[0], timeout=DEFAULT_GET_TIMEOUT)
  File "/usr/local/anaconda3/envs/edge-cloud-resource-allocation/lib/python3.6/site-packages/ray/_private/client_mode_hook.py", line 105, in wrapper
    return func(*args, **kwargs)
  File "/usr/local/anaconda3/envs/edge-cloud-resource-allocation/lib/python3.6/site-packages/ray/worker.py", line 1744, in get
    raise value
ray.exceptions.RayActorError: The actor died because of an error raised in its creation task, [36mray::PPOTrainer.__init__()[39m (pid=5578, ip=127.0.0.1)
  File "/usr/local/anaconda3/envs/edge-cloud-resource-allocation/lib/python3.6/site-packages/ray/rllib/agents/trainer.py", line 932, in _init
    raise NotImplementedError
NotImplementedError

During handling of the above exception, another exception occurred:

[36mray::PPOTrainer.__init__()[39m (pid=5578, ip=127.0.0.1)
  File "/usr/local/anaconda3/envs/edge-cloud-resource-allocation/lib/python3.6/site-packages/ray/rllib/agents/trainer.py", line 730, in __init__
    sync_function_tpl)
  File "/usr/local/anaconda3/envs/edge-cloud-resource-allocation/lib/python3.6/site-packages/ray/tune/trainable.py", line 122, in __init__
    self.setup(copy.deepcopy(self.config))
  File "/usr/local/anaconda3/envs/edge-cloud-resource-allocation/lib/python3.6/site-packages/ray/rllib/agents/trainer.py", line 832, in setup
    num_workers=self.config["num_workers"])
  File "/usr/local/anaconda3/envs/edge-cloud-resource-allocation/lib/python3.6/site-packages/ray/rllib/agents/trainer.py", line 1947, in _make_workers
    logdir=self.logdir,
  File "/usr/local/anaconda3/envs/edge-cloud-resource-allocation/lib/python3.6/site-packages/ray/rllib/evaluation/worker_set.py", line 102, in __init__
    lambda p, pid: (pid, p.observation_space, p.action_space)))
ray.exceptions.RayActorError: The actor died because of an error raised in its creation task, [36mray::RolloutWorker.__init__()[39m (pid=5574, ip=127.0.0.1)
  File "/usr/local/anaconda3/envs/edge-cloud-resource-allocation/lib/python3.6/site-packages/ray/rllib/evaluation/rollout_worker.py", line 457, in __init__
    self.env = env_creator(copy.deepcopy(self.env_context))
  File "/usr/local/anaconda3/envs/edge-cloud-resource-allocation/lib/python3.6/site-packages/ray/rllib/agents/trainer.py", line 2600, in <lambda>
    register_env(name, lambda cfg: env_object(cfg))
  File "/Users/fan/OneDrive - University of Southampton/My-Projects/Edge-Cloud-Resource-Allocation/marl-edge-cloud/src/environments/edge_cloud/simulation/environment.py", line 140, in __init__
    strftime('_%Y_%m_%d_%T')), filemode='w', format=fmtStr)
  File "/usr/local/anaconda3/envs/edge-cloud-resource-allocation/lib/python3.6/logging/__init__.py", line 1808, in basicConfig
    h = FileHandler(filename, mode)
  File "/usr/local/anaconda3/envs/edge-cloud-resource-allocation/lib/python3.6/logging/__init__.py", line 1032, in __init__
    StreamHandler.__init__(self, self._open())
  File "/usr/local/anaconda3/envs/edge-cloud-resource-allocation/lib/python3.6/logging/__init__.py", line 1061, in _open
    return open(self.baseFilename, self.mode, encoding=self.encoding)
FileNotFoundError: [Errno 2] No such file or directory: '/Users/fan/OneDrive - University of Southampton/My-Projects/Edge-Cloud-Resource-Allocation/marl-edge-cloud/simulations/hyperparamter_optimisation__model_depth/logs/edge_cloud_resource_allocation_2022_03_27_10:59:05.log'

